Workbook

Sheet Feuille 1
B1: CAISSE FRAÎCHE — Calcul de coupe
B2: Le contreplaque n'est pas soumis a la norme NIMP 15 etant de base traite a la colle, a la pression et au chaud, et si moins de 0.6 mm
B3: Boulon zingue | C3: Boulon
B4: Insert filete bois he[agonale | C4: Insert
C6: Longueur cote le +long | D6: largeur cote court | E6: Hauteur | F6: Plaques 122x250 - Avant/Arriere + Gauche/Droite | G6: Plaques 122x250 - Contreplaque Haut/Bas | H6: Planches brutes 300cm necessaires | I6: Epaisseur CP Int
A7: Qt | B7: Dimensions interieures | C7: ='Feuille 2'!C8 -> 75 | D7: ='Feuille 2'!E8 -> 98 | E7: ='Feuille 2'!G8 -> 100 | I7: 0.5
A8: 2 | B8: Contrepalque Avant/Arriere | C8: =C7 -> 75 | E8: =E7 -> 100 | F8: =IF(AND(MIN(C8,E8)<=61,MAX(C8,E8)<=250),0.5*A8,IF(AND(MIN(C8,E8)<=122,MAX(C8,E8)<=125),0.5*A8,IF(AND(MIN(C8,E8)>61,MIN(C8,E8)<=122,MAX(C8,E8)>125,MAX(C8,E8)<=250),1*A8,IF(AND(MIN(C8,E8)>122,MIN(C8,E8)<=244,MAX(C8,E8)<=250),2*A8,"Hors limites")))) -> 1 | I8: Epaisseur Planche
A9: 4 | B9: Planche verticale court | C9: =E8-2*I11 -> 86 | H9: =IF(C9<=0,"Hors limites",IF(C9<=75,ROUNDUP(A9/4,0),IF(C9<=100,ROUNDUP(A9/3,0),IF(C9<=150,ROUNDUP(A9/2,0),IF(C9<=300,ROUNDUP(A9/1,0),"Hors limites"))))) -> 2 | I9: 3.5
A10: 2 | B10: Planche verticale milieu | C10: =E8-2*I11 -> 86 | H10: =IF(C10<=0,"Hors limites",IF(C10<=75,ROUNDUP(A10/4,0),IF(C10<=100,ROUNDUP(A10/3,0),IF(C10<=150,ROUNDUP(A10/2,0),IF(C10<=300,ROUNDUP(A10/1,0),"Hors limites"))))) -> 1 | I10: Largeur Planche
A11: 2 | B11: Planche horizontal milieu | C11: =C8 -> 75 | H11: =IF(C11<=0,"Hors limites",IF(C11<=75,ROUNDUP(A11/4,0),IF(C11<=100,ROUNDUP(A11/3,0),IF(C11<=150,ROUNDUP(A11/2,0),IF(C11<=300,ROUNDUP(A11/1,0),"Hors limites"))))) -> 1 | I11: 7
A12: 4 | B12: Planche horizontale Long | C12: =C8 -> 75 | H12: =IF(C12<=0,"Hors limites",IF(C12<=75,ROUNDUP(A12/4,0),IF(C12<=100,ROUNDUP(A12/3,0),IF(C12<=150,ROUNDUP(A12/2,0),IF(C12<=300,ROUNDUP(A12/1,0),"Hors limites"))))) -> 1 | I12: Epaisseur CP Ext
A13: 2 | B13: Contrepalque Gauche/Droite | D13: =D7+2*(2*I9+I7) -> 113 | E13: =E7 -> 100 | F13: =IF(AND(MIN(D13,E13)<=61,MAX(D13,E13)<=250),0.5*A13,IF(AND(MIN(D13,E13)<=122,MAX(D13,E13)<=125),0.5*A13,IF(AND(MIN(D13,E13)>61,MIN(D13,E13)<=122,MAX(D13,E13)>125,MAX(D13,E13)<=250),1*A13,IF(AND(MIN(D13,E13)>122,MIN(D13,E13)<=244,MAX(D13,E13)<=250),2*A13,"Hors limites")))) -> 1 | I13: 1.5
A14: 4 | B14: Planche verticale courte | C14: =E13-2*I11 -> 86 | H14: =IF(C14<=0,"Hors limites",IF(C14<=75,ROUNDUP(A14/4,0),IF(C14<=100,ROUNDUP(A14/3,0),IF(C14<=150,ROUNDUP(A14/2,0),IF(C14<=300,ROUNDUP(A14/1,0),"Hors limites"))))) -> 2
A15: 2 | B15: Planche horizontal milieu | C15: =D13-2*I11 -> 99 | H15: =IF(C15<=0,"Hors limites",IF(C15<=75,ROUNDUP(A15/4,0),IF(C15<=100,ROUNDUP(A15/3,0),IF(C15<=150,ROUNDUP(A15/2,0),IF(C15<=300,ROUNDUP(A15/1,0),"Hors limites"))))) -> 1
A16: 4 | B16: Planche horizontale longue | C16: =D13 -> 113 | H16: =IF(C16<=0,"Hors limites",IF(C16<=75,ROUNDUP(A16/4,0),IF(C16<=100,ROUNDUP(A16/3,0),IF(C16<=150,ROUNDUP(A16/2,0),IF(C16<=300,ROUNDUP(A16/1,0),"Hors limites"))))) -> 2
A17: 2 | B17: Contrepalque Haut/Bas | C17: =C8+2*(I9+I7) -> 83 | D17: =D13 -> 113 | G17: =IF(AND(MIN(C17,D17)<=61,MAX(C17,D17)<=250),0.5*A17,IF(AND(MIN(C17,D17)<=122,MAX(C17,D17)<=125),0.5*A17,IF(AND(MIN(C17,D17)>61,MIN(C17,D17)<=122,MAX(C17,D17)>125,MAX(C17,D17)<=250),1*A17,IF(AND(MIN(C17,D17)>122,MIN(C17,D17)<=244,MAX(C17,D17)<=250),2*A17,"Hors limites")))) -> 1
A18: 4 | B18: Planche pour passage du transpalette | D18: =D17 -> 113 | H18: =IF(D18<=0,"Hors limites",IF(D18<=75,ROUNDUP(A18/4,0),IF(D18<=100,ROUNDUP(A18/3,0),IF(D18<=150,ROUNDUP(A18/2,0),IF(D18<=300,ROUNDUP(A18/1,0),"Hors limites"))))) -> 2
B19: Dimensions Exterieures | C19: =C17 -> 83 | D19: =D17 -> 113 | E19: =E7+2*I13 -> 103
B20: Planche en cml | C20: =A9*C9+A10*C10+A11*C11+A12*C12+A14*C14+A15*C15+A16*C16+A18*D18 -> 2412
B21: TOTAL | F21: =SUM(F8:F19) -> 2 | G21: =SUM(G8:G19) -> 1 | H21: =SUM(H8:H19) -> 12
A22: 36 | B22: Boulon / Insert

Sheet Feuille 1 - Objet 2
B1: CAISSE FRAÎCHE — Calcul de coupe
B2: Le contreplaque n'est pas soumis a la norme NIMP 15 etant de base traite a la colle, a la pression et au chaud, et si moins de 0.6 mm
B3: Boulon zingue | C3: Boulon
B4: Insert filete bois he[agonale | C4: Insert
C6: Longueur cote le +long | D6: largeur cote court | E6: Hauteur | F6: Plaques 122x250 - Avant/Arriere + Gauche/Droite | G6: Plaques 122x250 - Contreplaque Haut/Bas | H6: Planches brutes 300cm necessaires | I6: Epaisseur CP Int
A7: Qt | B7: Dimensions interieures | C7: ='Feuille 2'!C12 -> 125 | D7: ='Feuille 2'!E12 -> 68 | E7: ='Feuille 2'!G12 -> 180 | I7: 0.5
A8: 2 | B8: Contrepalque Avant/Arriere | C8: =C7 -> 125 | E8: =E7 -> 180 | F8: =IF(AND(MIN(C8,E8)<=61,MAX(C8,E8)<=250),0.5*A8,IF(AND(MIN(C8,E8)<=122,MAX(C8,E8)<=125),0.5*A8,IF(AND(MIN(C8,E8)>61,MIN(C8,E8)<=122,MAX(C8,E8)>125,MAX(C8,E8)<=250),1*A8,IF(AND(MIN(C8,E8)>122,MIN(C8,E8)<=244,MAX(C8,E8)<=250),2*A8,"Hors limites")))) -> 4 | I8: Epaisseur Planche
A9: 4 | B9: Planche verticale court | C9: =E8-2*I11 -> 166 | H9: =IF(C9<=0,"Hors limites",IF(C9<=75,ROUNDUP(A9/4,0),IF(C9<=100,ROUNDUP(A9/3,0),IF(C9<=150,ROUNDUP(A9/2,0),IF(C9<=300,ROUNDUP(A9/1,0),"Hors limites"))))) -> 4 | I9: 3.5
A10: 2 | B10: Planche verticale milieu | C10: =E8-2*I11 -> 166 | H10: =IF(C10<=0,"Hors limites",IF(C10<=75,ROUNDUP(A10/4,0),IF(C10<=100,ROUNDUP(A10/3,0),IF(C10<=150,ROUNDUP(A10/2,0),IF(C10<=300,ROUNDUP(A10/1,0),"Hors limites"))))) -> 2 | I10: Largeur Planche
A11: 2 | B11: Planche horizontal milieu | C11: =C8 -> 125 | H11: =IF(C11<=0,"Hors limites",IF(C11<=75,ROUNDUP(A11/4,0),IF(C11<=100,ROUNDUP(A11/3,0),IF(C11<=150,ROUNDUP(A11/2,0),IF(C11<=300,ROUNDUP(A11/1,0),"Hors limites"))))) -> 1 | I11: 7
A12: 4 | B12: Planche horizontale Long | C12: =C8 -> 125 | H12: =IF(C12<=0,"Hors limites",IF(C12<=75,ROUNDUP(A12/4,0),IF(C12<=100,ROUNDUP(A12/3,0),IF(C12<=150,ROUNDUP(A12/2,0),IF(C12<=300,ROUNDUP(A12/1,0),"Hors limites"))))) -> 2 | I12: Epaisseur CP Ext
A13: 2 | B13: Contrepalque Gauche/Droite | D13: =D7+2*(2*I9+I7) -> 83 | E13: =E7 -> 180 | F13: =IF(AND(MIN(D13,E13)<=61,MAX(D13,E13)<=250),0.5*A13,IF(AND(MIN(D13,E13)<=122,MAX(D13,E13)<=125),0.5*A13,IF(AND(MIN(D13,E13)>61,MIN(D13,E13)<=122,MAX(D13,E13)>125,MAX(D13,E13)<=250),1*A13,IF(AND(MIN(D13,E13)>122,MIN(D13,E13)<=244,MAX(D13,E13)<=250),2*A13,"Hors limites")))) -> 2 | I13: 1.5
A14: 4 | B14: Planche verticale courte | C14: =E13-2*I11 -> 166 | H14: =IF(C14<=0,"Hors limites",IF(C14<=75,ROUNDUP(A14/4,0),IF(C14<=100,ROUNDUP(A14/3,0),IF(C14<=150,ROUNDUP(A14/2,0),IF(C14<=300,ROUNDUP(A14/1,0),"Hors limites"))))) -> 4
A15: 2 | B15: Planche horizontal milieu | C15: =D13-2*I11 -> 69 | H15: =IF(C15<=0,"Hors limites",IF(C15<=75,ROUNDUP(A15/4,0),IF(C15<=100,ROUNDUP(A15/3,0),IF(C15<=150,ROUNDUP(A15/2,0),IF(C15<=300,ROUNDUP(A15/1,0),"Hors limites"))))) -> 1
A16: 4 | B16: Planche horizontale longue | C16: =D13 -> 83 | H16: =IF(C16<=0,"Hors limites",IF(C16<=75,ROUNDUP(A16/4,0),IF(C16<=100,ROUNDUP(A16/3,0),IF(C16<=150,ROUNDUP(A16/2,0),IF(C16<=300,ROUNDUP(A16/1,0),"Hors limites"))))) -> 2
A17: 2 | B17: Contrepalque Haut/Bas | C17: =C8+2*(I9+I7) -> 133 | D17: =D13 -> 83 | G17: =IF(AND(MIN(C17,D17)<=61,MAX(C17,D17)<=250),0.5*A17,IF(AND(MIN(C17,D17)<=122,MAX(C17,D17)<=125),0.5*A17,IF(AND(MIN(C17,D17)>61,MIN(C17,D17)<=122,MAX(C17,D17)>125,MAX(C17,D17)<=250),1*A17,IF(AND(MIN(C17,D17)>122,MIN(C17,D17)<=244,MAX(C17,D17)<=250),2*A17,"Hors limites")))) -> 2
A18: 4 | B18: Planche pour passage du transpalette | D18: =D17 -> 83 | H18: =IF(D18<=0,"Hors limites",IF(D18<=75,ROUNDUP(A18/4,0),IF(D18<=100,ROUNDUP(A18/3,0),IF(D18<=150,ROUNDUP(A18/2,0),IF(D18<=300,ROUNDUP(A18/1,0),"Hors limites"))))) -> 2
B19: Dimensions Exterieures | C19: =C17 -> 133 | D19: =D17 -> 83 | E19: =E7+2*I13 -> 183
B20: Planche en cml | C20: =A9*C9+A10*C10+A11*C11+A12*C12+A14*C14+A15*C15+A16*C16+A18*D18 -> 3212
B21: TOTAL | F21: =SUM(F8:F19) -> 6 | G21: =SUM(G8:G19) -> 2 | H21: =SUM(H8:H19) -> 18
A22: 36 | B22: Boulon / Insert

Sheet Feuille 2
B1: CAISSE FRAÎCHE by LIRAA | E1: DEVIS
B2: 106 RUE BRACION, 75014 PARIS | E2: N° de devis | F2: 1 | G2: ="DEV-"&YEAR($F$3)&"-"&TEXT(MONTH($F$3),"00")&"-"&TEXT($F$2,"000") -> DEV-2026-09-001
B3: SIRET : | C3: À compléter | E3: Date d'émission | F3: =TODAY() -> 46279
E4: Date de validité | F4: =F3+30 -> 46309
B6: OBJET DU DEVIS — OBJET 1
B7: Nature de l'objet | C7: Sculpture | D7: Poids (kg) | E7: 12
B8: Longueur (cm) | C8: 75 | D8: Largeur (cm) | E8: 98 | F8: Hauteur (cm) | G8: 100
B10: OBJET DU DEVIS — OBJET 2 (si plusieurs caisses)
B11: Nature de l'objet | D11: Poids (kg)
B12: Longueur (cm) | C12: 125 | D12: Largeur (cm) | E12: 68 | F12: Hauteur (cm) | G12: 180
B14: DESTINATAIRE DU DEVIS
B15: Nom / Prénom ou Société
B16: Adresse de facturation
B17: Adresse email
B18: SIRET (si société)
B20: DÉLAI DE FABRICATION / LIVRAISON
B21: Délai choisi | C21: 2 à 4 jours | D21: Coefficient main d'oeuvre | E21: =IF(C21="2 jours",1.2,1) -> 1 | F21: Taux TVA | G21: 0.2
B23: OPTIONS SUPPLÉMENTAIRES
B24: Option | C24: Sélectionné (Oui/Non) | D24: Prix TTC | E24: Description
B25: Photogrammétrie | C25: Non | D25: 60 | E25: Afin de ne pas déplacer votre objet jusqu'à notre atelier, nous venons prendre son empreinte 3D, envoyée directement à nos équipes pour la réalisation d'un calage intérieur au mm. Ainsi l'objet ne se déplace jamais sans être protégé.
B26: Livraison de la caisse | C26: Non | D26: 80 | E26: Livraison de la caisse à l'adresse de facturation dans la journée.
B27: Mise en caisse | C27: Non | D27: 150 | E27: Nous nous chargeons de la mise en boîte de votre objet. Au-delà de 120 kg, nous vous invitons à nous contacter par téléphone.
B28: Monte-charge | C28: Non | D28: 180 | E28: Pour toute sortie de l'objet nécessitant une descente du 1er au 7e étage, nous prenons en charge la commande d'un dispositif approprié.
B29: Transport | C29: Non | D29: 100 | E29: Nous assurons un transport vers les aéroports de Paris, ou tout autre lieu de livraison dans Paris et la petite couronne.
B30: TOTAL OPTIONS TTC | D30: =SUMPRODUCT((C25:C29="Oui")*D25:D29) -> 0
B32: DÉTAIL DU DEVIS — OBJET 1
A33: Qt | B33: Matériaux | C33: Prix matériau unité HT | D33: Main d'oeuvre/unité HT | E33: Main d'oeuvre total HT | F33: Prix matériau TTC (unité) | G33: Prix total matériaux TTC | H33: Main d'oeuvre total TTC | I33: Coeff. main d'oeuvre (délai)
A34: ='Feuille 1'!F21 -> 2 | B34: Contreplaqué 5mm | C34: 13.92 | D34: 30 | E34: =D34*A34 -> 60 | F34: =C34*(1+$G$21) -> 16.704 | G34: =A34*F34 -> 33.408 | H34: =E34*(1+$G$21)*$E$21 -> 72 | I34: =$E$21 -> 1
A35: ='Feuille 1'!G21 -> 1 | B35: Contreplaqué 15mm | C35: 35 | D35: 40 | E35: =D35*A35 -> 40 | F35: =C35*(1+$G$21) -> 42 | G35: =A35*F35 -> 42 | H35: =E35*(1+$G$21)*$E$21 -> 48 | I35: =$E$21 -> 1
A36: ='Feuille 1'!H21 -> 12 | B36: Planches | C36: 6.75 | D36: 9 | E36: =D36*A36 -> 108 | F36: =C36*(1+$G$21) -> 8.1 | G36: =A36*F36 -> 97.2 | H36: =E36*(1+$G$21)*$E$21 -> 129.6 | I36: =$E$21 -> 1
A37: ='Feuille 1'!A22 -> 36 | B37: Insert, Boulon, vis, clous | C37: 0.15 | D37: 0 | E37: =D37*A37 -> 0 | F37: =C37*(1+$G$21) -> 0.18 | G37: =A37*F37 -> 6.48 | H37: =E37*(1+$G$21)*$E$21 -> 0 | I37: =$E$21 -> 1
B38: SOUS-TOTAL OBJET 1 | G38: =SUM(G34:G37) -> 179.088 | H38: =SUM(H34:H37) -> 249.6
B40: DÉTAIL DU DEVIS — OBJET 2 (si plusieurs caisses)
A41: Qt | B41: Matériaux | C41: Prix matériau unité HT | D41: Main d'oeuvre/unité HT | E41: Main d'oeuvre total HT | F41: Prix matériau TTC (unité) | G41: Prix total matériaux TTC | H41: Main d'oeuvre total TTC | I41: Coeff. main d'oeuvre (délai)
A42: =IF($C$12="",0,'Feuille 1 - Objet 2'!F21) -> 6 | B42: Contreplaqué 5mm | C42: 13.92 | D42: 30 | E42: =D42*A42 -> 180 | F42: =C42*(1+$G$21) -> 16.704 | G42: =A42*F42 -> 100.224 | H42: =E42*(1+$G$21)*$E$21 -> 216 | I42: =$E$21 -> 1
A43: =IF($C$12="",0,'Feuille 1 - Objet 2'!G21) -> 2 | B43: Contreplaqué 15mm | C43: 35 | D43: 40 | E43: =D43*A43 -> 80 | F43: =C43*(1+$G$21) -> 42 | G43: =A43*F43 -> 84 | H43: =E43*(1+$G$21)*$E$21 -> 96 | I43: =$E$21 -> 1
A44: =IF($C$12="",0,'Feuille 1 - Objet 2'!H21) -> 18 | B44: Planches | C44: 6.75 | D44: 9 | E44: =D44*A44 -> 162 | F44: =C44*(1+$G$21) -> 8.1 | G44: =A44*F44 -> 145.8 | H44: =E44*(1+$G$21)*$E$21 -> 194.4 | I44: =$E$21 -> 1
A45: =IF($C$12="",0,'Feuille 1 - Objet 2'!A22) -> 36 | B45: Insert, Boulon, vis, clous | C45: 0.15 | D45: 0 | E45: =D45*A45 -> 0 | F45: =C45*(1+$G$21) -> 0.18 | G45: =A45*F45 -> 6.48 | H45: =E45*(1+$G$21)*$E$21 -> 0 | I45: =$E$21 -> 1
B46: SOUS-TOTAL OBJET 2 | G46: =SUM(G42:G45) -> 336.504 | H46: =SUM(H42:H45) -> 506.4
B48: TOTAL DEVIS TTC | H48: =G38+H38+G46+H46+D30 -> 1271.592
...
